package exception;

public class Exception02 {
	public static void main(String[] args) {
		// try-catch-finally文の開始
		try {
			// tryブロック：例外が発生する可能性がある処理を記述
			System.out.println("100 ÷ 0は？");
			// Exception01と同じく、例外が発生
			int result = 100 / 0;
			System.out.println("計算結果" + result);
		// ArithmeticExceptionクラスの例外が発生した場合の例外処理
		} catch (ArithmeticException e) {
			// 例外クラスが一致するので、例外処理が実行される
			System.out.println("例外が発生");
		} finally {
			// 例外発生しても処理を実行
			System.out.println("プログラム終了");
		}
	}
}


//try-catch文（try-catch-finally文）の構文(例外処理を記述するために使用)
//try {
//    tryブロック（例外が発生する可能性がある処理）
//} catch (例外クラス 変数名) {
//    catchブロック（例外が発生した時に実行する処理）
//} catch (例外クラス 変数名) {
//    catchブロック（例外が発生した時に実行する処理）
//} finally {
//    finallyブロック(例外発生の有無にかかわらず必ず実行する処理)
//} {
